Workbook

Sheet predictwithfallbackConfidences
S1: Weighted confs | AD1: Weighted sums | AK1: Weighted cat+acc | AY1: Weighted cat+acc sums | BF1: Basic sums | BX1: Accuracy weight
A2: request_text | B2: category | C2: Prediction | D2: model_used | E2: Log_reg prediction | F2: Multi_nb prediction | G2: log_road_conf | H2: l_s_c | I2: l_ws_c | J2: l_wr_c | K2: nb_road_conf | L2: n_s_c | M2: n_ws_c | N2: n_wr_c | S2: Log road | T2: safety | U2: waste | V2: water | X2: NB Road | Y2: safety | Z2: waste | AA2: water | AD2: road | AE2: safety | AF2: waste | AG2: water | AK2: road | AL2: safety | AM2: waste | AN2: water | AQ2: road | AR2: safety | AS2: waste | AT2: water | AW2: Correct | AX2: Max conf | AZ2: road | BA2: safety | BB2: waste | BC2: water | BF2: road | BG2: safety | BH2: waste | BI2: water | BO2: Log road | BP2: safety | BQ2: waste | BR2: water | BS2: NB Road | BT2: safety | BU2: waste | BV2: water | BX2: Log road | BY2: safety | BZ2: waste | CA2: water | CB2: NB Road | CC2: safety | CD2: waste | CE2: water
A3: large pothole outside colombo street causing cars to swerve | B3: road | C3: road | D3: log_reg | E3: road | F3: safety | G3: 0.27125581 | H3: 0.2700946 | I3: 0.2206016 | J3: 0.23804798 | K3: 0.25051653 | L3: 0.26302926 | M3: 0.22634749 | N3: 0.26010672 | O3: =MAX(G3:J3) -> 0.27125581 | Q3: =IF(R3=B3,1,0) -> 1 | R3: {=_xlfn.IFS(S3=MAX(S3:V3),"road",T3=MAX(S3:V3),"safety",U3=MAX(S3:V3),"waste",V3=MAX(S3:V3),"water")} -> road | S3: =G3*G$85 -> 0.21248372 | T3: =H3*H$85 -> 0.1935678 | U3: =I3*I$85 -> 0.1691279 | V3: =J3*J$85 -> 0.17456852 | X3: =K3*K$85 -> 0.2212896 | Y3: =L3*L$85 -> 0.19727194 | Z3: =M3*M$85 -> 0.15089833 | AA3: =N3*N$85 -> 0.1820747 | AB3: =IF(AC3=B3,1,0) -> 1 | AC3: {=_xlfn.IFS(AD3=MAX(AD3:AG3),"road",AE3=MAX(AD3:AG3),"safety",AF3=MAX(AD3:AG3),"waste",AG3=MAX(AD3:AG3),"water")} -> road | AD3: =SUM(S3*Q66,X3) -> 0.44591525 | AE3: =SUM(T3*R66,Y3) -> 0.19727194 | AF3: =SUM(U3*S66,Z3) -> 0.15089833 | AG3: =SUM(V3*T66,AA3) -> 0.1820747 | AI3: =IF(AJ3=B3,1,0) -> 1 | AJ3: {=_xlfn.IFS(AK3=MAX(AK3:AN3),"road",AL3=MAX(AK3:AN3),"safety",AM3=MAX(AK3:AN3),"waste",AN3=MAX(AK3:AN3),"water")} -> road | AK3: =(G3*G$85)*G$86 -> 0.19477674 | AL3: =(H3*H$85)*H$86 -> 0.16775876 | AM3: =(I3*I$85)*I$86 -> 0.13812111 | AN3: =(J3*J$85)*J$86 -> 0.13674534 | AO3: =IF(AP3=$B3,1,0) -> 1 | AP3: {=_xlfn.IFS(AQ3=MAX(AQ3:AT3),"road",AR3=MAX(AQ3:AT3),"safety",AS3=MAX(AQ3:AT3),"waste",AT3=MAX(AQ3:AT3),"water")} -> road | AQ3: =(K3*K$85)*K$86 -> 0.20653696 | AR3: =(L3*L$85)*L$86 -> 0.17754475 | AS3: =(M3*M$85)*M$86 -> 0.12323364 | AT3: =(N3*N$85)*N$86 -> 0.1395906 | AW3: =IF(AY3=B3,1,0) -> 1 | AX3: =MAX(AZ3:BC3) -> 0.40131371 | AY3: {=_xlfn.IFS(AZ3=MAX(AZ3:BC3),"road",BA3=MAX(AZ3:BC3),"safety",BB3=MAX(AZ3:BC3),"waste",BC3=MAX(AZ3:BC3),"water")} -> road | AZ3: =SUM(AK3,AQ3) -> 0.40131371 | BA3: =SUM(AL3,AR3) -> 0.34530351 | BB3: =SUM(AM3,AS3) -> 0.26135475 | BC3: =SUM(AN3,AT3) -> 0.27633595 | BF3: =G3+K3 -> 0.52177234 | BG3: =H3+L3 -> 0.53312386 | BH3: =I3+M3 -> 0.4469491 | BI3: =J3+N3 -> 0.4981547 | BK3: =IF(BL3=B3,1,0) -> 1 | BL3: {=_xlfn.IFS(BO3=MAX(BO3:BV3),"road",BR3=MAX(BO3:BV3),"water",BT3=MAX(BO3:BV3),"safety",BU3=MAX(BO3:BV3),"waste",BV3=MAX(BO3:BV3),"water")} -> road | BM3: =IF(BN3=B3,1,0) -> 1 | BN3: {=_xlfn.IFS(BO3=MAX(BO3:BR3),"road",BP3=MAX(BO3:BR3),"safety",BQ3=MAX(BO3:BR3),"waste",BR3=MAX(BO3:BR3),"water")} -> road | BO3: =G3/(G$64/120) -> 2.5038998 | BP3: =H3/(H$64/120) -> 1.9065501 | BQ3: =I3/(I$64/120) -> 1.8908709 | BR3: =J3/(J$64/120) -> 1.7853599 | BS3: =K3/(K$64/$E$65) -> 2.1472846 | BT3: =L3/(L$64/$E$65) -> 1.052117 | BU3: =M3/(M$64/$E$65) -> 0.67904248 | BV3: =N3/(N$64/$E$65) -> 0.86702238
A4: glass and loose gravel left on cycle lane near hagley park | B4: road | C4: waste | D4: multi_nb | E4: safety | F4: waste | G4: 0.23614757 | H4: 0.27318369 | I4: 0.25754065 | J4: 0.2331281 | K4: 0.21727619 | L4: 0.27234181 | M4: 0.28794124 | N4: 0.22244076 | O4: =MAX(G4:J4) -> 0.27318369 | Q4: =IF(R4=B4,1,0) -> 0 | R4: {=_xlfn.IFS(S4=MAX(S4:V4),"road",T4=MAX(S4:V4),"safety",U4=MAX(S4:V4),"waste",V4=MAX(S4:V4),"water")} -> waste | S4: =G4*G$85 -> 0.18498226 | T4: =H4*H$85 -> 0.19578164 | U4: =I4*I$85 -> 0.19744783 | V4: =J4*J$85 -> 0.1709606 | X4: =K4*K$85 -> 0.1919273 | Y4: =L4*L$85 -> 0.20425636 | Z4: =M4*M$85 -> 0.19196083 | AA4: =N4*N$85 -> 0.15570853 | AB4: =IF(AC4=B4,1,0) -> 0 | AC4: {=_xlfn.IFS(AD4=MAX(AD4:AG4),"road",AE4=MAX(AD4:AG4),"safety",AF4=MAX(AD4:AG4),"waste",AG4=MAX(AD4:AG4),"water")} -> safety | AD4: =SUM(S4*Q67,X4) -> 0.1919273 | AE4: =SUM(T4*R67,Y4) -> 0.20425636 | AF4: =SUM(U4*S67,Z4) -> 0.19196083 | AG4: =SUM(V4*T67,AA4) -> 0.15570853 | AI4: =IF(AJ4=B4,1,0) -> 0 | AJ4: {=_xlfn.IFS(AK4=MAX(AK4:AN4),"road",AL4=MAX(AK4:AN4),"safety",AM4=MAX(AK4:AN4),"waste",AN4=MAX(AK4:AN4),"water")} -> safety | AK4: =(G4*G$85)*G$86 -> 0.16956707 | AL4: =(H4*H$85)*H$86 -> 0.16967742 | AM4: =(I4*I$85)*I$86 -> 0.16124906 | AN4: =(J4*J$85)*J$86 -> 0.13391914 | AO4: =IF(AP4=$B4,1,0) -> 0 | AP4: {=_xlfn.IFS(AQ4=MAX(AQ4:AT4),"road",AR4=MAX(AQ4:AT4),"safety",AS4=MAX(AQ4:AT4),"waste",AT4=MAX(AQ4:AT4),"water")} -> safety | AQ4: =(K4*K$85)*K$86 -> 0.17913215 | AR4: =(L4*L$85)*L$86 -> 0.18383072 | AS4: =(M4*M$85)*M$86 -> 0.15676801 | AT4: =(N4*N$85)*N$86 -> 0.11937654 | AW4: =IF(AY4=B4,1,0) -> 0 | AX4: =MAX(AZ4:BC4) -> 0.35350814 | AY4: {=_xlfn.IFS(AZ4=MAX(AZ4:BC4),"road",BA4=MAX(AZ4:BC4),"safety",BB4=MAX(AZ4:BC4),"waste",BC4=MAX(AZ4:BC4),"water")} -> safety | AZ4: =SUM(AK4,AQ4) -> 0.34869922 | BA4: =SUM(AL4,AR4) -> 0.35350814 | BB4: =SUM(AM4,AS4) -> 0.31801707 | BC4: =SUM(AN4,AT4) -> 0.25329568 | BF4: =G4+K4 -> 0.45342376 | BG4: =H4+L4 -> 0.5455255 | BH4: =I4+M4 -> 0.54548189 | BI4: =J4+N4 -> 0.45556885 | BK4: =IF(BL4=B4,1,0) -> #N/A | BL4: {=_xlfn.IFS(BO4=MAX(BO4:BV4),"road",BR4=MAX(BO4:BV4),"water",BT4=MAX(BO4:BV4),"safety",BU4=MAX(BO4:BV4),"waste",BV4=MAX(BO4:BV4),"water")} -> #N/A | BM4: =IF(BN4=B4,1,0) -> 0 | BN4: {=_xlfn.IFS(BO4=MAX(BO4:BR4),"road",BP4=MAX(BO4:BR4),"safety",BQ4=MAX(BO4:BR4),"waste",BR4=MAX(BO4:BR4),"water")} -> waste | BO4: =G4/(G$64/120) -> 2.1798237 | BP4: =H4/(H$64/120) -> 1.9283554 | BQ4: =I4/(I$64/120) -> 2.2074913 | BR4: =J4/(J$64/120) -> 1.7484607 | BS4: =K4/(K$64/$E$65) -> 1.8623674 | BT4: =L4/(L$64/$E$65) -> 1.0893672 | BU4: =M4/(M$64/$E$65) -> 0.86382373 | BV4: =N4/(N$64/$E$65) -> 0.74146919
A5: traffic light at moorhouse avenue not changing for pedestrians | B5: road | C5: road | D5: log_reg | E5: road | F5: road | G5: 0.32296654 | H5: 0.24323425 | I5: 0.23059599 | J5: 0.20320322 | K5: 0.31536209 | L5: 0.22824987 | M5: 0.22870312 | N5: 0.22768491 | O5: =MAX(G5:J5) -> 0.32296654 | Q5: =IF(R5=B5,1,0) -> 1 | R5: {=_xlfn.IFS(S5=MAX(S5:V5),"road",T5=MAX(S5:V5),"safety",U5=MAX(S5:V5),"waste",V5=MAX(S5:V5),"water")} -> road | S5: =G5*G$85 -> 0.25299046 | T5: =H5*H$85 -> 0.17431788 | U5: =I5*I$85 -> 0.17679026 | V5: =J5*J$85 -> 0.1490157 | X5: =K5*K$85 -> 0.27856985 | Y5: =L5*L$85 -> 0.1711874 | Z5: =M5*M$85 -> 0.15246875 | AA5: =N5*N$85 -> 0.15937944 | AB5: =IF(AC5=B5,1,0) -> 1 | AC5: {=_xlfn.IFS(AD5=MAX(AD5:AG5),"road",AE5=MAX(AD5:AG5),"safety",AF5=MAX(AD5:AG5),"waste",AG5=MAX(AD5:AG5),"water")} -> road | AD5: =SUM(S5*Q68,X5) -> 0.27856985 | AE5: =SUM(T5*R68,Y5) -> 0.1711874 | AF5: =SUM(U5*S68,Z5) -> 0.15246875 | AG5: =SUM(V5*T68,AA5) -> 0.15937944 | AI5: =IF(AJ5=B5,1,0) -> 1 | AJ5: {=_xlfn.IFS(AK5=MAX(AK5:AN5),"road",AL5=MAX(AK5:AN5),"safety",AM5=MAX(AK5:AN5),"waste",AN5=MAX(AK5:AN5),"water")} -> road | AK5: =(G5*G$85)*G$86 -> 0.23190792 | AL5: =(H5*H$85)*H$86 -> 0.15107549 | AM5: =(I5*I$85)*I$86 -> 0.14437871 | AN5: =(J5*J$85)*J$86 -> 0.11672896 | AO5: =IF(AP5=$B5,1,0) -> 1 | AP5: {=_xlfn.IFS(AQ5=MAX(AQ5:AT5),"road",AR5=MAX(AQ5:AT5),"safety",AS5=MAX(AQ5:AT5),"waste",AT5=MAX(AQ5:AT5),"water")} -> road | AQ5: =(K5*K$85)*K$86 -> 0.25999852 | AR5: =(L5*L$85)*L$86 -> 0.15406866 | AS5: =(M5*M$85)*M$86 -> 0.12451615 | AT5: =(N5*N$85)*N$86 -> 0.1221909 | AW5: =IF(AY5=B5,1,0) -> 1 | AX5: =MAX(AZ5:BC5) -> 0.49190644 | AY5: {=_xlfn.IFS(AZ5=MAX(AZ5:BC5),"road",BA5=MAX(AZ5:BC5),"safety",BB5=MAX(AZ5:BC5),"waste",BC5=MAX(AZ5:BC5),"water")} -> road | AZ5: =SUM(AK5,AQ5) -> 0.49190644 | BA5: =SUM(AL5,AR5) -> 0.30514416 | BB5: =SUM(AM5,AS5) -> 0.26889486 | BC5: =SUM(AN5,AT5) -> 0.23891986 | BF5: =G5+K5 -> 0.63832863 | BG5: =H5+L5 -> 0.47148412 | BH5: =I5+M5 -> 0.45929911 | BI5: =J5+N5 -> 0.43088813 | BK5: =IF(BL5=B5,1,0) -> 1 | BL5: {=_xlfn.IFS(BO5=MAX(BO5:BV5),"road",BR5=MAX(BO5:BV5),"water",BT5=MAX(BO5:BV5),"safety",BU5=MAX(BO5:BV5),"waste",BV5=MAX(BO5:BV5),"water")} -> road | BM5: =IF(BN5=B5,1,0) -> 1 | BN5: {=_xlfn.IFS(BO5=MAX(BO5:BR5),"road",BP5=MAX(BO5:BR5),"safety",BQ5=MAX(BO5:BR5),"waste",BR5=MAX(BO5:BR5),"water")} -> road | BO5: =G5/(G$64/120) -> 2.9812296 | BP5: =H5/(H$64/120) -> 1.7169476 | BQ5: =I5/(I$64/120) -> 1.9765371 | BR5: =J5/(J$64/120) -> 1.5240242 | BS5: =K5/(K$64/$E$65) -> 2.7031036 | BT5: =L5/(L$64/$E$65) -> 0.91299949 | BU5: =M5/(M$64/$E$65) -> 0.68610937 | BV5: =N5/(N$64/$E$65) -> 0.75894971
A6: deep crack forming on footpath beside the primary school | B6: road | C6: road | D6: log_reg | E6: road | F6: road | G6: 0.29866343 | H6: 0.2816122 | I6: 0.20679452 | J6: 0.21292985 | K6: 0.28041326 | L6: 0.25051913 | M6: 0.2164531 | N6: 0.2526145 | O6: =MAX(G6:J6) -> 0.29866343 | Q6: =IF(R6=B6,1,0) -> 1 | R6: {=_xlfn.IFS(S6=MAX(S6:V6),"road",T6=MAX(S6:V6),"safety",U6=MAX(S6:V6),"waste",V6=MAX(S6:V6),"water")} -> road | S6: =G6*G$85 -> 0.23395302 | T6: =H6*H$85 -> 0.20182208 | U6: =I6*I$85 -> 0.15854247 | V6: =J6*J$85 -> 0.15614856 | X6: =K6*K$85 -> 0.24769838 | Y6: =L6*L$85 -> 0.18788935 | Z6: =M6*M$85 -> 0.14430207 | AA6: =N6*N$85 -> 0.17683015 | AB6: =IF(AC6=B6,1,0) -> 1 | AC6: {=_xlfn.IFS(AD6=MAX(AD6:AG6),"road",AE6=MAX(AD6:AG6),"safety",AF6=MAX(AD6:AG6),"waste",AG6=MAX(AD6:AG6),"water")} -> road | AD6: =SUM(S6*Q69,X6) -> 0.24769838 | AE6: =SUM(T6*R69,Y6) -> 0.18788935 | AF6: =SUM(U6*S69,Z6) -> 0.14430207 | AG6: =SUM(V6*T69,AA6) -> 0.17683015 | AI6: =IF(AJ6=B6,1,0) -> 1 | AJ6: {=_xlfn.IFS(AK6=MAX(AK6:AN6),"road",AL6=MAX(AK6:AN6),"safety",AM6=MAX(AK6:AN6),"waste",AN6=MAX(AK6:AN6),"water")} -> road | AK6: =(G6*G$85)*G$86 -> 0.21445693 | AL6: =(H6*H$85)*H$86 -> 0.17491247 | AM6: =(I6*I$85)*I$86 -> 0.12947635 | AN6: =(J6*J$85)*J$86 -> 0.12231637 | AO6: =IF(AP6=$B6,1,0) -> 1 | AP6: {=_xlfn.IFS(AQ6=MAX(AQ6:AT6),"road",AR6=MAX(AQ6:AT6),"safety",AS6=MAX(AQ6:AT6),"waste",AT6=MAX(AQ6:AT6),"water")} -> road | AQ6: =(K6*K$85)*K$86 -> 0.23118516 | AR6: =(L6*L$85)*L$86 -> 0.16910042 | AS6: =(M6*M$85)*M$86 -> 0.11784669 | AT6: =(N6*N$85)*N$86 -> 0.13556978 | AW6: =IF(AY6=B6,1,0) -> 1 | AX6: =MAX(AZ6:BC6) -> 0.44564209 | AY6: {=_xlfn.IFS(AZ6=MAX(AZ6:BC6),"road",BA6=MAX(AZ6:BC6),"safety",BB6=MAX(AZ6:BC6),"waste",BC6=MAX(AZ6:BC6),"water")} -> road | AZ6: =SUM(AK6,AQ6) -> 0.44564209 | BA6: =SUM(AL6,AR6) -> 0.34401288 | BB6: =SUM(AM6,AS6) -> 0.24732304 | BC6: =SUM(AN6,AT6) -> 0.25788615 | BF6: =G6+K6 -> 0.57907669 | BG6: =H6+L6 -> 0.53213134 | BH6: =I6+M6 -> 0.42324762 | BI6: =J6+N6 -> 0.46554435 | BK6: =IF(BL6=B6,1,0) -> 1 | BL6: {=_xlfn.IFS(BO6=MAX(BO6:BV6),"road",BR6=MAX(BO6:BV6),"water",BT6=MAX(BO6:BV6),"safety",BU6=MAX(BO6:BV6),"waste",BV6=MAX(BO6:BV6),"water")} -> road | BM6: =IF(BN6=B6,1,0) -> 1 | BN6: {=_xlfn.IFS(BO6=MAX(BO6:BR6),"road",BP6=MAX(BO6:BR6),"safety",BQ6=MAX(BO6:BR6),"waste",BR6=MAX(BO6:BR6),"water")} -> road | BO6: =G6/(G$64/120) -> 2.7568932 | BP6: =H6/(H$64/120) -> 1.9878508 | BQ6: =I6/(I$64/120) -> 1.7725245 | BR6: =J6/(J$64/120) -> 1.5969739 | BS6: =K6/(K$64/$E$65) -> 2.4035423 | BT6: =L6/(L$64/$E$65) -> 1.0020765 | BU6: =M6/(M$64/$E$65) -> 0.64935931 | BV6: =N6/(N$64/$E$65) -> 0.84204833
A7: street sign has fallen over after strong winds | B7: road | C7: water | D7: log_reg | E7: water | F7: water | G7: 0.25716566 | H7: 0.22663399 | I7: 0.25003939 | J7: 0.26616097 | K7: 0.23357715 | L7: 0.20176422 | M7: 0.26336788 | N7: 0.30129075 | O7: =MAX(G7:J7) -> 0.26616097 | Q7: =IF(R7=B7,1,0) -> 1 | R7: {=_xlfn.IFS(S7=MAX(S7:V7),"road",T7=MAX(S7:V7),"safety",U7=MAX(S7:V7),"waste",V7=MAX(S7:V7),"water")} -> road | S7: =G7*G$85 -> 0.20144643 | T7: =H7*H$85 -> 0.16242103 | U7: =I7*I$85 -> 0.19169686 | V7: =J7*J$85 -> 0.19518471 | X7: =K7*K$85 -> 0.20632649 | Y7: =L7*L$85 -> 0.15132317 | Z7: =M7*M$85 -> 0.17557859 | AA7: =N7*N$85 -> 0.21090352 | AB7: =IF(AC7=B7,1,0) -> 0 | AC7: {=_xlfn.IFS(AD7=MAX(AD7:AG7),"road",AE7=MAX(AD7:AG7),"safety",AF7=MAX(AD7:AG7),"waste",AG7=MAX(AD7:AG7),"water")} -> water | AD7: =SUM(S7*Q70,X7) -> 0.20632649 | AE7: =SUM(T7*R70,Y7) -> 0.15132317 | AF7: =SUM(U7*S70,Z7) -> 0.17557859 | AG7: =SUM(V7*T70,AA7) -> 0.21090352 | AI7: =IF(AJ7=B7,1,0) -> 1 | AJ7: {=_xlfn.IFS(AK7=MAX(AK7:AN7),"road",AL7=MAX(AK7:AN7),"safety",AM7=MAX(AK7:AN7),"waste",AN7=MAX(AK7:AN7),"water")} -> road | AK7: =(G7*G$85)*G$86 -> 0.18465923 | AL7: =(H7*H$85)*H$86 -> 0.14076489 | AM7: =(I7*I$85)*I$86 -> 0.15655244 | AN7: =(J7*J$85)*J$86 -> 0.15289469 | AO7: =IF(AP7=$B7,1,0) -> 1 | AP7: {=_xlfn.IFS(AQ7=MAX(AQ7:AT7),"road",AR7=MAX(AQ7:AT7),"safety",AS7=MAX(AQ7:AT7),"waste",AT7=MAX(AQ7:AT7),"water")} -> road | AQ7: =(K7*K$85)*K$86 -> 0.19257139 | AR7: =(L7*L$85)*L$86 -> 0.13619085 | AS7: =(M7*M$85)*M$86 -> 0.14338918 | AT7: =(N7*N$85)*N$86 -> 0.1616927 | AW7: =IF(AY7=B7,1,0) -> 1 | AX7: =MAX(AZ7:BC7) -> 0.37723062 | AY7: {=_xlfn.IFS(AZ7=MAX(AZ7:BC7),"road",BA7=MAX(AZ7:BC7),"safety",BB7=MAX(AZ7:BC7),"waste",BC7=MAX(AZ7:BC7),"water")} -> road | AZ7: =SUM(AK7,AQ7) -> 0.37723062 | BA7: =SUM(AL7,AR7) -> 0.27695574 | BB7: =SUM(AM7,AS7) -> 0.29994162 | BC7: =SUM(AN7,AT7) -> 0.31458739 | BF7: =G7+K7 -> 0.49074281 | BG7: =H7+L7 -> 0.42839821 | BH7: =I7+M7 -> 0.51340727 | BI7: =J7+N7 -> 0.56745171 | BK7: =IF(BL7=B7,1,0) -> 1 | BL7: {=_xlfn.IFS(BO7=MAX(BO7:BV7),"road",BR7=MAX(BO7:BV7),"water",BT7=MAX(BO7:BV7),"safety",BU7=MAX(BO7:BV7),"waste",BV7=MAX(BO7:BV7),"water")} -> road | BM7: =IF(BN7=B7,1,0) -> 1 | BN7: {=_xlfn.IFS(BO7=MAX(BO7:BR7),"road",BP7=MAX(BO7:BR7),"safety",BQ7=MAX(BO7:BR7),"waste",BR7=MAX(BO7:BR7),"water")} -> road | BO7: =G7/(G$64/120) -> 2.3738368 | BP7: =H7/(H$64/120) -> 1.5997693 | BQ7: =I7/(I$64/120) -> 2.1431947 | BR7: =J7/(J$64/120) -> 1.9962072 | BS7: =K7/(K$64/$E$65) -> 2.0020899 | BT7: =L7/(L$64/$E$65) -> 0.80705689 | BU7: =M7/(M$64/$E$65) -> 0.79010364 | BV7: =N7/(N$64/$E$65) -> 1.0043025
A8: road marking at the roundabout has faded and is hard to see at night | B8: road | C8: safety | D8: log_reg | E8: safety | F8: safety | G8: 0.27269601 | H8: 0.29383887 | I8: 0.23589671 | J8: 0.1975684 | K8: 0.25920849 | L8: 0.28232197 | M8: 0.22873624 | N8: 0.2297333 | O8: =MAX(G8:J8) -> 0.29383887 | Q8: =IF(R8=B8,1,0) -> 1 | R8: {=_xlfn.IFS(S8=MAX(S8:V8),"road",T8=MAX(S8:V8),"safety",U8=MAX(S8:V8),"waste",V8=MAX(S8:V8),"water")} -> road | S8: =G8*G$85 -> 0.21361188 | T8: =H8*H$85 -> 0.21058452 | U8: =I8*I$85 -> 0.18085415 | V8: =J8*J$85 -> 0.1448835 | X8: =K8*K$85 -> 0.2289675 | Y8: =L8*L$85 -> 0.21174148 | Z8: =M8*M$85 -> 0.15249083 | AA8: =N8*N$85 -> 0.16081331 | AB8: =IF(AC8=B8,1,0) -> 1 | AC8: {=_xlfn.IFS(AD8=MAX(AD8:AG8),"road",AE8=MAX(AD8:AG8),"safety",AF8=MAX(AD8:AG8),"waste",AG8=MAX(AD8:AG8),"water")} -> road | AD8: =SUM(S8*Q71,X8) -> 0.2289675 | AE8: =SUM(T8*R71,Y8) -> 0.21174148 | AF8: =SUM(U8*S71,Z8) -> 0.15249083 | AG8: =SUM(V8*T71,AA8) -> 0.16081331 | AI8: =IF(AJ8=B8,1,0) -> 1 | AJ8: {=_xlfn.IFS(AK8=MAX(AK8:AN8),"road",AL8=MAX(AK8:AN8),"safety",AM8=MAX(AK8:AN8),"waste",AN8=MAX(AK8:AN8),"water")} -> road | AK8: =(G8*G$85)*G$86 -> 0.19581089 | AL8: =(H8*H$85)*H$86 -> 0.18250659 | AM8: =(I8*I$85)*I$86 -> 0.14769755 | AN8: =(J8*J$85)*J$86 -> 0.11349207 | AO8: =IF(AP8=$B8,1,0) -> 1 | AP8: {=_xlfn.IFS(AQ8=MAX(AQ8:AT8),"road",AR8=MAX(AQ8:AT8),"safety",AS8=MAX(AQ8:AT8),"waste",AT8=MAX(AQ8:AT8),"water")} -> road | AQ8: =(K8*K$85)*K$86 -> 0.213703 | AR8: =(L8*L$85)*L$86 -> 0.19056733 | AS8: =(M8*M$85)*M$86 -> 0.12453418 | AT8: =(N8*N$85)*N$86 -> 0.1232902 | AW8: =IF(AY8=B8,1,0) -> 1 | AX8: =MAX(AZ8:BC8) -> 0.40951389 | AY8: {=_xlfn.IFS(AZ8=MAX(AZ8:BC8),"road",BA8=MAX(AZ8:BC8),"safety",BB8=MAX(AZ8:BC8),"waste",BC8=MAX(AZ8:BC8),"water")} -> road | AZ8: =SUM(AK8,AQ8) -> 0.40951389 | BA8: =SUM(AL8,AR8) -> 0.37307392 | BB8: =SUM(AM8,AS8) -> 0.27223173 | BC8: =SUM(AN8,AT8) -> 0.23678228 | BF8: =G8+K8 -> 0.5319045 | BG8: =H8+L8 -> 0.57616084 | BH8: =I8+M8 -> 0.46463295 | BI8: =J8+N8 -> 0.4273017 | BK8: =IF(BL8=B8,1,0) -> 1 | BL8: {=_xlfn.IFS(BO8=MAX(BO8:BV8),"road",BR8=MAX(BO8:BV8),"water",BT8=MAX(BO8:BV8),"safety",BU8=MAX(BO8:BV8),"waste",BV8=MAX(BO8:BV8),"water")} -> road | BM8: =IF(BN8=B8,1,0) -> 1 | BN8: {=_xlfn.IFS(BO8=MAX(BO8:BR8),"road",BP8=MAX(BO8:BR8),"safety",BQ8=MAX(BO8:BR8),"waste",BR8=MAX(BO8:BR8),"water")} -> road | BO8: =G8/(G$64/120) -> 2.517194 | BP8: =H8/(H$64/120) -> 2.0741567 | BQ8: =I8/(I$64/120) -> 2.0219718 | BR8: =J8/(J$64/120) -> 1.481763 | BS8: =K8/(K$64/$E$65) -> 2.2217871 | BT8: =L8/(L$64/$E$65) -> 1.1292879 | BU8: =M8/(M$64/$E$65) -> 0.68620872 | BV8: =N8/(N$64/$E$65) -> 0.76577767
A9: stormwater grate is loose and making loud noise when buses pass | B9: road | C9: safety | D9: log_reg | E9: safety | F9: safety | G9: 0.30604365 | H9: 0.33868057 | I9: 0.17107894 | J9: 0.18419684 | K9: 0.26328692 | L9: 0.2885222 | M9: 0.19331363 | N9: 0.25487725 | O9: =MAX(G9:J9) -> 0.33868057 | Q9: =IF(R9=B9,1,0) -> 0 | R9: {=_xlfn.IFS(S9=MAX(S9:V9),"road",T9=MAX(S9:V9),"safety",U9=MAX(S9:V9),"waste",V9=MAX(S9:V9),"water")} -> safety | S9: =G9*G$85 -> 0.23973419 | T9: =H9*H$85 -> 0.24272107 | U9: =I9*I$85 -> 0.13116052 | V9: =J9*J$85 -> 0.13507768 | X9: =K9*K$85 -> 0.23257011 | Y9: =L9*L$85 -> 0.21639165 | Z9: =M9*M$85 -> 0.12887575 | AA9: =N9*N$85 -> 0.17841408 | AB9: =IF(AC9=B9,1,0) -> 1 | AC9: {=_xlfn.IFS(AD9=MAX(AD9:AG9),"road",AE9=MAX(AD9:AG9),"safety",AF9=MAX(AD9:AG9),"waste",AG9=MAX(AD9:AG9),"water")} -> road | AD9: =SUM(S9*Q72,X9) -> 0.23257011 | AE9: =SUM(T9*R72,Y9) -> 0.21639165 | AF9: =SUM(U9*S72,Z9) -> 0.12887575 | AG9: =SUM(V9*T72,AA9) -> 0.17841408 | AI9: =IF(AJ9=B9,1,0) -> 1 | AJ9: {=_xlfn.IFS(AK9=MAX(AK9:AN9),"road",AL9=MAX(AK9:AN9),"safety",AM9=MAX(AK9:AN9),"waste",AN9=MAX(AK9:AN9),"water")} -> road | AK9: =(G9*G$85)*G$86 -> 0.21975634 | AL9: =(H9*H$85)*H$86 -> 0.21035826 | AM9: =(I9*I$85)*I$86 -> 0.10711443 | AN9: =(J9*J$85)*J$86 -> 0.10581085 | AO9: =IF(AP9=$B9,1,0) -> 1 | AP9: {=_xlfn.IFS(AQ9=MAX(AQ9:AT9),"road",AR9=MAX(AQ9:AT9),"safety",AS9=MAX(AQ9:AT9),"waste",AT9=MAX(AQ9:AT9),"water")} -> road | AQ9: =(K9*K$85)*K$86 -> 0.21706544 | AR9: =(L9*L$85)*L$86 -> 0.19475248 | AS9: =(M9*M$85)*M$86 -> 0.10524853 | AT9: =(N9*N$85)*N$86 -> 0.13678413 | AW9: =IF(AY9=B9,1,0) -> 1 | AX9: =MAX(AZ9:BC9) -> 0.43682178 | AY9: {=_xlfn.IFS(AZ9=MAX(AZ9:BC9),"road",BA9=MAX(AZ9:BC9),"safety",BB9=MAX(AZ9:BC9),"waste",BC9=MAX(AZ9:BC9),"water")} -> road | AZ9: =SUM(AK9,AQ9) -> 0.43682178 | BA9: =SUM(AL9,AR9) -> 0.40511075 | BB9: =SUM(AM9,AS9) -> 0.21236296 | BC9: =SUM(AN9,AT9) -> 0.24259498 | BF9: =G9+K9 -> 0.56933057 | BG9: =H9+L9 -> 0.62720277 | BH9: =I9+M9 -> 0.36439257 | BI9: =J9+N9 -> 0.43907409 | BK9: =IF(BL9=B9,1,0) -> 1 | BL9: {=_xlfn.IFS(BO9=MAX(BO9:BV9),"road",BR9=MAX(BO9:BV9),"water",BT9=MAX(BO9:BV9),"safety",BU9=MAX(BO9:BV9),"waste",BV9=MAX(BO9:BV9),"water")} -> road | BM9: =IF(BN9=B9,1,0) -> 1 | BN9: {=_xlfn.IFS(BO9=MAX(BO9:BR9),"road",BP9=MAX(BO9:BR9),"safety",BQ9=MAX(BO9:BR9),"waste",BR9=MAX(BO9:BR9),"water")} -> road | BO9: =G9/(G$64/120) -> 2.8250183 | BP9: =H9/(H$64/120) -> 2.3906864 | BQ9: =I9/(I$64/120) -> 1.4663909 | BR9: =J9/(J$64/120) -> 1.3814763 | BS9: =K9/(K$64/$E$65) -> 2.256745 | BT9: =L9/(L$64/$E$65) -> 1.1540888 | BU9: =M9/(M$64/$E$65) -> 0.57994089 | BV9: =N9/(N$64/$E$65) -> 0.84959084
A10: broken curb stone on corner is blocking pram access | B10: road | C10: safety | D10: log_reg | E10: safety | F10: safety | G10: 0.23619506 | H10: 0.3672945 | I10: 0.23031189 | J10: 0.16619856 | K10: 0.22248052 | L10: 0.34533347 | M10: 0.24426794 | N10: 0.18791808 | O10: =MAX(G10:J10) -> 0.3672945 | Q10: =IF(R10=B10,1,0) -> 0 | R10: {=_xlfn.IFS(S10=MAX(S10:V10),"road",T10=MAX(S10:V10),"safety",U10=MAX(S10:V10),"waste",V10=MAX(S10:V10),"water")} -> safety | S10: =G10*G$85 -> 0.18501946 | T10: =H10*H$85 -> 0.26322772 | U10: =I10*I$85 -> 0.17657245 | V10: =J10*J$85 -> 0.12187894 | X10: =K10*K$85 -> 0.19652446 | Y10: =L10*L$85 -> 0.2590001 | Z10: =M10*M$85 -> 0.16284529 | AA10: =N10*N$85 -> 0.13154266 | AB10: =IF(AC10=B10,1,0) -> 0 | AC10: {=_xlfn.IFS(AD10=MAX(AD10:AG10),"road",AE10=MAX(AD10:AG10),"safety",AF10=MAX(AD10:AG10),"waste",AG10=MAX(AD10:AG10),"water")} -> safety | AD10: =SUM(S10*Q73,X10) -> 0.19652446 | AE10: =SUM(T10*R73,Y10) -> 0.2590001 | AF10: =SUM(U10*S73,Z10) -> 0.16284529 | AG10: =SUM(V10*T73,AA10) -> 0.13154266 | AI10: =IF(AJ10=B10,1,0) -> 0 | AJ10: {=_xlfn.IFS(AK10=MAX(AK10:AN10),"road",AL10=MAX(AK10:AN10),"safety",AM10=MAX(AK10:AN10),"waste",AN10=MAX(AK10:AN10),"water")} -> safety | AK10: =(G10*G$85)*G$86 -> 0.16960118 | AL10: =(H10*H$85)*H$86 -> 0.22813069 | AM10: =(I10*I$85)*I$86 -> 0.14420083 | AN10: =(J10*J$85)*J$86 -> 0.095471837 | AO10: =IF(AP10=$B10,1,0) -> 0 | AP10: {=_xlfn.IFS(AQ10=MAX(AQ10:AT10),"road",AR10=MAX(AQ10:AT10),"safety",AS10=MAX(AQ10:AT10),"waste",AT10=MAX(AQ10:AT10),"water")} -> safety | AQ10: =(K10*K$85)*K$86 -> 0.18342283 | AR10: =(L10*L$85)*L$86 -> 0.23310009 | AS10: =(M10*M$85)*M$86 -> 0.13299032 | AT10: =(N10*N$85)*N$86 -> 0.10084937 | AW10: =IF(AY10=B10,1,0) -> 0 | AX10: =MAX(AZ10:BC10) -> 0.46123078 | AY10: {=_xlfn.IFS(AZ10=MAX(AZ10:BC10),"road",BA10=MAX(AZ10:BC10),"safety",BB10=MAX(AZ10:BC10),"waste",BC10=MAX(AZ10:BC10),"water")} -> safety | AZ10: =SUM(AK10,AQ10) -> 0.353024 | BA10: =SUM(AL10,AR10) -> 0.46123078 | BB10: =SUM(AM10,AS10) -> 0.27719115 | BC10: =SUM(AN10,AT10) -> 0.19632121 | BF10: =G10+K10 -> 0.45867558 | BG10: =H10+L10 -> 0.71262797 | BH10: =I10+M10 -> 0.47457982 | BI10: =J10+N10 -> 0.35411663 | BK10: =IF(BL10=B10,1,0) -> #N/A | BL10: {=_xlfn.IFS(BO10=MAX(BO10:BV10),"road",BR10=MAX(BO10:BV10),"water",BT10=MAX(BO10:BV10),"safety",BU10=MAX(BO10:BV10),"waste",BV10=MAX(BO10:BV10),"water")} -> #N/A | BM10: =IF(BN10=B10,1,0) -> 0 | BN10: {=_xlfn.IFS(BO10=MAX(BO10:BR10),"road",BP10=MAX(BO10:BR10),"safety",BQ10=MAX(BO10:BR10),"waste",BR10=MAX(BO10:BR10),"water")} -> safety | BO10: =G10/(G$64/120) -> 2.1802621 | BP10: =H10/(H$64/120) -> 2.592667 | BQ10: =I10/(I$64/120) -> 1.9741019 | BR10: =J10/(J$64/120) -> 1.2464892 | BS10: =K10/(K$64/$E$65) -> 1.9069759 | BT10: =L10/(L$64/$E$65) -> 1.3813339 | BU10: =M10/(M$64/$E$65) -> 0.73280381 | BV10: =N10/(N$64/$E$65) -> 0.6263936
A11: several potholes along school dropoff area need urgent repair | B11: road | C11: waste | D11: log_reg | E11: waste | F11: waste | G11: 0.23043937 | H11: 0.2699842 | I11: 0.30983173 | J11: 0.1897447 | K11: 0.22100883 | L11: 0.26120209 | M11: 0.30076867 | N11: 0.2170204 | O11: =MAX(G11:J11) -> 0.30983173 | Q11: =IF(R11=B11,1,0) -> 0 | R11: {=_xlfn.IFS(S11=MAX(S11:V11),"road",T11=MAX(S11:V11),"safety",U11=MAX(S11:V11),"waste",V11=MAX(S11:V11),"water")} -> waste | S11: =G11*G$85 -> 0.18051084 | T11: =H11*H$85 -> 0.19348867 | U11: =I11*I$85 -> 0.23753766 | V11: =J11*J$85 -> 0.13914611 | X11: =K11*K$85 -> 0.19522447 | Y11: =L11*L$85 -> 0.19590157 | Z11: =M11*M$85 -> 0.20051245 | AA11: =N11*N$85 -> 0.15191428 | AB11: =IF(AC11=B11,1,0) -> 0 | AC11: {=_xlfn.IFS(AD11=MAX(AD11:AG11),"road",AE11=MAX(AD11:AG11),"safety",AF11=MAX(AD11:AG11),"waste",AG11=MAX(AD11:AG11),"water")} -> waste | AD11: =SUM(S11*Q74,X11) -> 0.19522447 | AE11: =SUM(T11*R74,Y11) -> 0.19590157 | AF11: =SUM(U11*S74,Z11) -> 0.20051245 | AG11: =SUM(V11*T74,AA11) -> 0.15191428 | AI11: =IF(AJ11=B11,1,0) -> 0 | AJ11: {=_xlfn.IFS(AK11=MAX(AK11:AN11),"road",AL11=MAX(AK11:AN11),"safety",AM11=MAX(AK11:AN11),"waste",AN11=MAX(AK11:AN11),"water")} -> waste | AK11: =(G11*G$85)*G$86 -> 0.16546827 | AL11: =(H11*H$85)*H$86 -> 0.16769018 | AM11: =(I11*I$85)*I$86 -> 0.19398909 | AN11: =(J11*J$85)*J$86 -> 0.10899779 | AO11: =IF(AP11=$B11,1,0) -> 1 | AP11: {=_xlfn.IFS(AQ11=MAX(AQ11:AT11),"road",AR11=MAX(AQ11:AT11),"safety",AS11=MAX(AQ11:AT11),"waste",AT11=MAX(AQ11:AT11),"water")} -> road | AQ11: =(K11*K$85)*K$86 -> 0.1822095 | AR11: =(L11*L$85)*L$86 -> 0.17631141 | AS11: =(M11*M$85)*M$86 -> 0.16375183 | AT11: =(N11*N$85)*N$86 -> 0.11646761 | AW11: =IF(AY11=B11,1,0) -> 0 | AX11: =MAX(AZ11:BC11) -> 0.35774092 | AY11: {=_xlfn.IFS(AZ11=MAX(AZ11:BC11),"road",BA11=MAX(AZ11:BC11),"safety",BB11=MAX(AZ11:BC11),"waste",BC11=MAX(AZ11:BC11),"water")} -> waste | AZ11: =SUM(AK11,AQ11) -> 0.34767778 | BA11: =SUM(AL11,AR11) -> 0.3440016 | BB11: =SUM(AM11,AS11) -> 0.35774092 | BC11: =SUM(AN11,AT11) -> 0.2254654 | BF11: =G11+K11 -> 0.45144821 | BG11: =H11+L11 -> 0.53118629 | BH11: =I11+M11 -> 0.61060041 | BI11: =J11+N11 -> 0.4067651 | BK11: =IF(BL11=B11,1,0) -> #N/A | BL11: {=_xlfn.IFS(BO11=MAX(BO11:BV11),"road",BR11=MAX(BO11:BV11),"water",BT11=MAX(BO11:BV11),"safety",BU11=MAX(BO11:BV11),"waste",BV11=MAX(BO11:BV11),"water")} -> #N/A | BM11: =IF(BN11=B11,1,0) -> 0 | BN11: {=_xlfn.IFS(BO11=MAX(BO11:BR11),"road",BP11=MAX(BO11:BR11),"safety",BQ11=MAX(BO11:BR11),"waste",BR11=MAX(BO11:BR11),"water")} -> waste | BO11: =G11/(G$64/120) -> 2.1271327 | BP11: =H11/(H$64/120) -> 1.9057708 | BQ11: =I11/(I$64/120) -> 2.6557006 | BR11: =J11/(J$64/120) -> 1.4230852 | BS11: =K11/(K$64/$E$65) -> 1.8943614 | BT11: =L11/(L$64/$E$65) -> 1.0448084 | BU11: =M11/(M$64/$E$65) -> 0.90230602 | BV11: =N11/(N$64/$E$65) -> 0.72340133
A12: loose metal on road shoulder is creating dust and safety risk | B12: road | C12: safety | D12: log_reg | E12: safety | F12: water | G12: 0.29784528 | H12: 0.31670176 | I12: 0.1845499 | J12: 0.20090306 | K12: 0.25133471 | L12: 0.27153544 | M12: 0.19297109 | N12: 0.28415876 | O12: =MAX(G12:J12) -> 0.31670176 | Q12: =IF(R12=B12,1,0) -> 1 | R12: {=_xlfn.IFS(S12=MAX(S12:V12),"road",T12=MAX(S12:V12),"safety",U12=MAX(S12:V12),"waste",V12=MAX(S12:V12),"water")} -> road | S12: =G12*G$85 -> 0.23331214 | T12: =H12*H$85 -> 0.22696959 | U12: =I12*I$85 -> 0.14148826 | V12: =J12*J$85 -> 0.14732891 | X12: =K12*K$85 -> 0.22201233 | Y12: =L12*L$85 -> 0.20365158 | Z12: =M12*M$85 -> 0.12864739 | AA12: =N12*N$85 -> 0.19891113 | AB12: =IF(AC12=B12,1,0) -> 1 | AC12: {=_xlfn.IFS(AD12=MAX(AD12:AG12),"road",AE12=MAX(AD12:AG12),"safety",AF12=MAX(AD12:AG12),"waste",AG12=MAX(AD12:AG12),"water")} -> road | AD12: =SUM(S12*Q75,X12) -> 0.22201233 | AE12: =SUM(T12*R75,Y12) -> 0.20365158 | AF12: =SUM(U12*S75,Z12) -> 0.12864739 | AG12: =SUM(V12*T75,AA12) -> 0.19891113 | AI12: =IF(AJ12=B12,1,0) -> 1 | AJ12: {=_xlfn.IFS(AK12=MAX(AK12:AN12),"road",AL12=MAX(AK12:AN12),"safety",AM12=MAX(AK12:AN12),"waste",AN12=MAX(AK12:AN12),"water")} -> road | AK12: =(G12*G$85)*G$86 -> 0.21386946 | AL12: =(H12*H$85)*H$86 -> 0.19670698 | AM12: =(I12*I$85)*I$86 -> 0.11554874 | AN12: =(J12*J$85)*J$86 -> 0.11540765 | AO12: =IF(AP12=$B12,1,0) -> 1 | AP12: {=_xlfn.IFS(AQ12=MAX(AQ12:AT12),"road",AR12=MAX(AQ12:AT12),"safety",AS12=MAX(AQ12:AT12),"waste",AT12=MAX(AQ12:AT12),"water")} -> road | AQ12: =(K12*K$85)*K$86 -> 0.20721151 | AR12: =(L12*L$85)*L$86 -> 0.18328642 | AS12: =(M12*M$85)*M$86 -> 0.10506204 | AT12: =(N12*N$85)*N$86 -> 0.15249853 | AW12: =IF(AY12=B12,1,0) -> 1 | AX12: =MAX(AZ12:BC12) -> 0.42108097 | AY12: {=_xlfn.IFS(AZ12=MAX(AZ12:BC12),"road",BA12=MAX(AZ12:BC12),"safety",BB12=MAX(AZ12:BC12),"waste",BC12=MAX(AZ12:BC12),"water")} -> road | AZ12: =SUM(AK12,AQ12) -> 0.42108097 | BA12: =SUM(AL12,AR12) -> 0.3799934 | BB12: =SUM(AM12,AS12) -> 0.22061078 | BC12: =SUM(AN12,AT12) -> 0.26790618 | BF12: =G12+K12 -> 0.54917999 | BG12: =H12+L12 -> 0.5882372 | BH12: =I12+M12 -> 0.37752099 | BI12: =J12+N12 -> 0.48506182 | BK12: =IF(BL12=B12,1,0) -> 1 | BL12: {=_xlfn.IFS(BO12=MAX(BO12:BV12),"road",BR12=MAX(BO12:BV12),"water",BT12=MAX(BO12:BV12),"safety",BU12=MAX(BO12:BV12),"waste",BV12=MAX(BO12:BV12),"water")} -> road | BM12: =IF(BN12=B12,1,0) -> 1 | BN12: {=_xlfn.IFS(BO12=MAX(BO12:BR12),"road",BP12=MAX(BO12:BR12),"safety",BQ12=MAX(BO12:BR12),"waste",BR12=MAX(BO12:BR12),"water")} -> road | BO12: =G12/(G$64/120) -> 2.7493411 | BP12: =H12/(H$64/120) -> 2.2355418 | BQ12: =I12/(I$64/120) -> 1.5818563 | BR12: =J12/(J$64/120) -> 1.506773 | BS12: =K12/(K$64/$E$65) -> 2.1542975 | BT12: =L12/(L$64/$E$65) -> 1.0861418 | BU12: =M12/(M$64/$E$65) -> 0.57891326 | BV12: =N12/(N$64/$E$65) -> 0.94719587
A13: missed rubbish collection for our street again this week | B13: waste | C13: waste | D13: log_reg | E13: waste | F13: waste | G13: 0.25856524 | H13: 0.1851045 | I13: 0.4012867 | J13: 0.15504356 | K13: 0.24122301 | L13: 0.18387871 | M13: 0.39191178 | N13: 0.1829865 | O13: =MAX(G13:J13) -> 0.4012867 | Q13: =IF(R13=B13,1,0) -> 1 | R13: {=_xlfn.IFS(S13=MAX(S13:V13),"road",T13=MAX(S13:V13),"safety",U13=MAX(S13:V13),"waste",V13=MAX(S13:V13),"water")} -> waste | S13: =G13*G$85 -> 0.20254277 | T13: =H13*H$85 -> 0.13265823 | U13: =I13*I$85 -> 0.30765314 | V13: =J13*J$85 -> 0.11369861 | X13: =K13*K$85 -> 0.21308033 | Y13: =L13*L$85 -> 0.13790903 | Z13: =M13*M$85 -> 0.26127452 | AA13: =N13*N$85 -> 0.12809055 | AB13: =IF(AC13=B13,1,0) -> 1 | AC13: {=_xlfn.IFS(AD13=MAX(AD13:AG13),"road",AE13=MAX(AD13:AG13),"safety",AF13=MAX(AD13:AG13),"waste",AG13=MAX(AD13:AG13),"water")} -> waste | AD13: =SUM(S13*Q76,X13) -> 0.21308033 | AE13: =SUM(T13*R76,Y13) -> 0.13790903 | AF13: =SUM(U13*S76,Z13) -> 0.26127452 | AG13: =SUM(V13*T76,AA13) -> 0.12809055 | AI13: =IF(AJ13=B13,1,0) -> 1 | AJ13: {=_xlfn.IFS(AK13=MAX(AK13:AN13),"road",AL13=MAX(AK13:AN13),"safety",AM13=MAX(AK13:AN13),"waste",AN13=MAX(AK13:AN13),"water")} -> waste | AK13: =(G13*G$85)*G$86 -> 0.1856642 | AL13: =(H13*H$85)*H$86 -> 0.11497046 | AM13: =(I13*I$85)*I$86 -> 0.25125006 | AN13: =(J13*J$85)*J$86 -> 0.089063913 | AO13: =IF(AP13=$B13,1,0) -> 1 | AP13: {=_xlfn.IFS(AQ13=MAX(AQ13:AT13),"road",AR13=MAX(AQ13:AT13),"safety",AS13=MAX(AQ13:AT13),"waste",AT13=MAX(AQ13:AT13),"water")} -> waste | AQ13: =(K13*K$85)*K$86 -> 0.19887497 | AR13: =(L13*L$85)*L$86 -> 0.12411813 | AS13: =(M13*M$85)*M$86 -> 0.21337419 | AT13: =(N13*N$85)*N$86 -> 0.098202755 | AW13: =IF(AY13=B13,1,0) -> 1 | AX13: =MAX(AZ13:BC13) -> 0.46462425 | AY13: {=_xlfn.IFS(AZ13=MAX(AZ13:BC13),"road",BA13=MAX(AZ13:BC13),"safety",BB13=MAX(AZ13:BC13),"waste",BC13=MAX(AZ13:BC13),"water")} -> waste | AZ13: =SUM(AK13,AQ13) -> 0.38453918 | BA13: =SUM(AL13,AR13) -> 0.23908859 | BB13: =SUM(AM13,AS13) -> 0.46462425 | BC13: =SUM(AN13,AT13) -> 0.18726667 | BF13: =G13+K13 -> 0.49978825 | BG13: =H13+L13 -> 0.36898321 | BH13: =I13+M13 -> 0.79319848 | BI13: =J13+N13 -> 0.33803006 | BK13: =IF(BL13=B13,1,0) -> #N/A | BL13: {=_xlfn.IFS(BO13=MAX(BO13:BV13),"road",BR13=MAX(BO13:BV13),"water",BT13=MAX(BO13:BV13),"safety",BU13=MAX(BO13:BV13),"waste",BV13=MAX(BO13:BV13),"water")} -> #N/A | BM13: =IF(BN13=B13,1,0) -> 1 | BN13: {=_xlfn.IFS(BO13=MAX(BO13:BR13),"road",BP13=MAX(BO13:BR13),"safety",BQ13=MAX(BO13:BR13),"waste",BR13=MAX(BO13:BR13),"water")} -> waste | BO13: =G13/(G$64/120) -> 2.386756 | BP13: =H13/(H$64/120) -> 1.30662 | BQ13: =I13/(I$64/120) -> 3.4396003 | BR13: =J13/(J$64/120) -> 1.1628267 | BS13: =K13/(K$64/$E$65) -> 2.0676258 | BT13: =L13/(L$64/$E$65) -> 0.73551483 | BU13: =M13/(M$64/$E$65) -> 1.1757353 | BV13: =N13/(N$64/$E$65) -> 0.609955
A14: recycling bins overflowing beside the community hall | B14: waste | C14: waste | D14: log_reg | E14: waste | F14: waste | G14: 0.22513592 | H14: 0.26532021 | I14: 0.32816778 | J14: 0.18137608 | K14: 0.20557498 | L14: 0.25377371 | M14: 0.33452289 | N14: 0.20612842 | O14: =MAX(G14:J14) -> 0.32816778 | Q14: =IF(R14=B14,1,0) -> 1 | R14: {=_xlfn.IFS(S14=MAX(S14:V14),"road",T14=MAX(S14:V14),"safety",U14=MAX(S14:V14),"waste",V14=MAX(S14:V14),"water")} -> waste | S14: =G14*G$85 -> 0.17635647 | T14: =H14*H$85 -> 0.19014615 | U14: =I14*I$85 -> 0.2515953 | V14: =J14*J$85 -> 0.13300913 | X14: =K14*K$85 -> 0.18159123 | Y14: =L14*L$85 -> 0.19033028 | Z14: =M14*M$85 -> 0.22301526 | AA14: =N14*N$85 -> 0.14428989 | AB14: =IF(AC14=B14,1,0) -> 1 | AC14: {=_xlfn.IFS(AD14=MAX(AD14:AG14),"road",AE14=MAX(AD14:AG14),"safety",AF14=MAX(AD14:AG14),"waste",AG14=MAX(AD14:AG14),"water")} -> waste | AD14: =SUM(S14*Q77,X14) -> 0.18159123 | AE14: =SUM(T14*R77,Y14) -> 0.19033028 | AF14: =SUM(U14*S77,Z14) -> 0.22301526 | AG14: =SUM(V14*T77,AA14) -> 0.14428989 | AI14: =IF(AJ14=B14,1,0) -> 1 | AJ14: {=_xlfn.IFS(AK14=MAX(AK14:AN14),"road",AL14=MAX(AK14:AN14),"safety",AM14=MAX(AK14:AN14),"waste",AN14=MAX(AK14:AN14),"water")} -> waste | AK14: =(G14*G$85)*G$86 -> 0.1616601 | AL14: =(H14*H$85)*H$86 -> 0.16479333 | AM14: =(I14*I$85)*I$86 -> 0.20546949 | AN14: =(J14*J$85)*J$86 -> 0.10419048 | AO14: =IF(AP14=$B14,1,0) -> 1 | AP14: {=_xlfn.IFS(AQ14=MAX(AQ14:AT14),"road",AR14=MAX(AQ14:AT14),"safety",AS14=MAX(AQ14:AT14),"waste",AT14=MAX(AQ14:AT14),"water")} -> waste | AQ14: =(K14*K$85)*K$86 -> 0.16948515 | AR14: =(L14*L$85)*L$86 -> 0.17129725 | AS14: =(M14*M$85)*M$86 -> 0.18212913 | AT14: =(N14*N$85)*N$86 -> 0.11062225 | AW14: =IF(AY14=B14,1,0) -> 1 | AX14: =MAX(AZ14:BC14) -> 0.38759862 | AY14: {=_xlfn.IFS(AZ14=MAX(AZ14:BC14),"road",BA14=MAX(AZ14:BC14),"safety",BB14=MAX(AZ14:BC14),"waste",BC14=MAX(AZ14:BC14),"water")} -> waste | AZ14: =SUM(AK14,AQ14) -> 0.33114525 | BA14: =SUM(AL14,AR14) -> 0.33609058 | BB14: =SUM(AM14,AS14) -> 0.38759862 | BC14: =SUM(AN14,AT14) -> 0.21481274 | BF14: =G14+K14 -> 0.43071091 | BG14: =H14+L14 -> 0.51909392 | BH14: =I14+M14 -> 0.66269067 | BI14: =J14+N14 -> 0.3875045 | BK14: =IF(BL14=B14,1,0) -> #N/A | BL14: {=_xlfn.IFS(BO14=MAX(BO14:BV14),"road",BR14=MAX(BO14:BV14),"water",BT14=MAX(BO14:BV14),"safety",BU14=MAX(BO14:BV14),"waste",BV14=MAX(BO14:BV14),"water")} -> #N/A | BM14: =IF(BN14=B14,1,0) -> 1 | BN14: {=_xlfn.IFS(BO14=MAX(BO14:BR14),"road",BP14=MAX(BO14:BR14),"safety",BQ14=MAX(BO14:BR14),"waste",BR14=MAX(BO14:BR14),"water")} -> waste | BO14: =G14/(G$64/120) -> 2.0781778 | BP14: =H14/(H$64/120) -> 1.8728485 | BQ14: =I14/(I$64/120) -> 2.8128667 | BR14: =J14/(J$64/120) -> 1.3603206 | BS14: =K14/(K$64/$E$65) -> 1.7620713 | BT14: =L14/(L$64/$E$65) -> 1.0150948 | BU14: =M14/(M$64/$E$65) -> 1.0035687 | BV14: =N14/(N$64/$E$65) -> 0.68709474
... A62: overhanging branch above the footpath looks unsafe | B62: safety | C62: safety | D62: log_reg | E62: safety | F62: safety | G62: 0.25164217 | H62: 0.36895393 | I62: 0.1899272 | J62: 0.18947671 | K62: 0.22155355 | L62: 0.35679238 | M62: 0.2003529 | N62: 0.22130116 | O62: =MAX(G62:J62) -> 0.36895393 | Q62: =IF(R62=B62,1,0) -> 1 | R62: {=_xlfn.IFS(S62=MAX(S62:V62),"road",T62=MAX(S62:V62),"safety",U62=MAX(S62:V62),"waste",V62=MAX(S62:V62),"water")} -> safety | S62: =G62*G$85 -> 0.1971197 | T62: =H62*H$85 -> 0.26441698 | U62: =I62*I$85 -> 0.14561085 | V62: =J62*J$85 -> 0.13894958 | X62: =K62*K$85 -> 0.19570563 | Y62: =L62*L$85 -> 0.26759429 | Z62: =M62*M$85 -> 0.1335686 | AA62: =N62*N$85 -> 0.15491082 | AB62: =IF(AC62=B62,1,0) -> 1 | AC62: {=_xlfn.IFS(AD62=MAX(AD62:AG62),"road",AE62=MAX(AD62:AG62),"safety",AF62=MAX(AD62:AG62),"waste",AG62=MAX(AD62:AG62),"water")} -> safety | AD62: =SUM(S62*Q125,X62) -> 0.19570563 | AE62: =SUM(T62*R125,Y62) -> 0.26759429 | AF62: =SUM(U62*S125,Z62) -> 0.1335686 | AG62: =SUM(V62*T125,AA62) -> 0.15491082 | AI62: =IF(AJ62=B62,1,0) -> 1 | AJ62: {=_xlfn.IFS(AK62=MAX(AK62:AN62),"road",AL62=MAX(AK62:AN62),"safety",AM62=MAX(AK62:AN62),"waste",AN62=MAX(AK62:AN62),"water")} -> safety | AK62: =(G62*G$85)*G$86 -> 0.18069306 | AL62: =(H62*H$85)*H$86 -> 0.22916138 | AM62: =(I62*I$85)*I$86 -> 0.11891553 | AN62: =(J62*J$85)*J$86 -> 0.10884384 | AO62: =IF(AP62=$B62,1,0) -> 1 | AP62: {=_xlfn.IFS(AQ62=MAX(AQ62:AT62),"road",AR62=MAX(AQ62:AT62),"safety",AS62=MAX(AQ62:AT62),"waste",AT62=MAX(AQ62:AT62),"water")} -> safety | AQ62: =(K62*K$85)*K$86 -> 0.18265859 | AR62: =(L62*L$85)*L$86 -> 0.24083486 | AS62: =(M62*M$85)*M$86 -> 0.10908103 | AT62: =(N62*N$85)*N$86 -> 0.11876496 | AW62: =IF(AY62=B62,1,0) -> 1 | AX62: =MAX(AZ62:BC62) -> 0.46999624 | AY62: {=_xlfn.IFS(AZ62=MAX(AZ62:BC62),"road",BA62=MAX(AZ62:BC62),"safety",BB62=MAX(AZ62:BC62),"waste",BC62=MAX(AZ62:BC62),"water")} -> safety | AZ62: =SUM(AK62,AQ62) -> 0.36335165 | BA62: =SUM(AL62,AR62) -> 0.46999624 | BB62: =SUM(AM62,AS62) -> 0.22799656 | BC62: =SUM(AN62,AT62) -> 0.2276088 | BF62: =G62+K62 -> 0.47319571 | BG62: =H62+L62 -> 0.72574631 | BH62: =I62+M62 -> 0.3902801 | BI62: =J62+N62 -> 0.41077787 | BK62: =IF(BL62=B62,1,0) -> #N/A | BL62: {=_xlfn.IFS(BO62=MAX(BO62:BV62),"road",BR62=MAX(BO62:BV62),"water",BT62=MAX(BO62:BV62),"safety",BU62=MAX(BO62:BV62),"waste",BV62=MAX(BO62:BV62),"water")} -> #N/A | BM62: =IF(BN62=B62,1,0) -> 1 | BN62: {=_xlfn.IFS(BO62=MAX(BO62:BR62),"road",BP62=MAX(BO62:BR62),"safety",BQ62=MAX(BO62:BR62),"waste",BR62=MAX(BO62:BR62),"water")} -> safety | BO62: =G62/(G$64/120) -> 2.3228508 | BP62: =H62/(H$64/120) -> 2.6043807 | BQ62: =I62/(I$64/120) -> 1.6279474 | BR62: =J62/(J$64/120) -> 1.4210753 | BS62: =K62/(K$64/$E$65) -> 1.8990304 | BT62: =L62/(L$64/$E$65) -> 1.4271695 | BU62: =M62/(M$64/$E$65) -> 0.60105871 | BV62: =N62/(N$64/$E$65) -> 0.73767055
F63: Weights | G63: road | H63: safety | I63: waste | J63: water | K63: road | L63: safety | M63: waste | N63: water | R63: =SUM(Q3:Q62) -> 39 | AC63: =SUM(AB:AB) -> 39 | AJ63: =SUM(AI:AI) -> 40 | AP63: =SUM(AO:AO) -> 41 | AY63: =SUM(AW:AW) -> 40 | BL63: =SUM(BK3:BK62) -> #N/A | BN63: =SUM(BM3:BM62) -> 38
E64: =SUM(G64:J64) -> 60 | F64: Count cat | G64: 13 | H64: 17 | I64: 14 | J64: 16 | K64: 7 | L64: 15 | M64: 20 | N64: 18
E65: =SUM(K64:N64) -> 60 | F65: Accuracy | G65: 5 | H65: 8 | I65: 11 | J65: 13 | K65: 4 | L65: 6 | M65: 11 | N65: 14 | O65: NB acc | P65: Log Acc | Q65: Acc diff
F66: acc% | G66: =G65/60 -> 0.083333333 | H66: =H65/60 -> 0.13333333 | I66: =I65/60 -> 0.18333333 | J66: =J65/60 -> 0.21666667 | K66: =K65/60 -> 0.066666667 | L66: =L65/60 -> 0.1 | M66: =M65/60 -> 0.18333333 | N66: =N65/60 -> 0.23333333 | O66: =SUM(K66:N66) -> 0.58333333 | P66: =SUM(G66:J66) -> 0.61666667 | Q66: =P66/O66 -> 1.0571429 | AJ66: =40/60 -> 0.66666667 | AN66: =41/60 -> 0.68333333
F67: false pos | G67: 8 | H67: 9 | I67: 3 | J67: 3 | K67: 3 | L67: 9 | M67: 9 | N67: 4
F68: prob false pos | G68: =G67/30 -> 0.26666667 | H68: =H67/30 -> 0.3 | I68: =I67/30 -> 0.1 | J68: =J67/30 -> 0.1 | K68: =K67/30 -> 0.1 | L68: =L67/30 -> 0.3 | M68: =M67/30 -> 0.3 | N68: =N67/30 -> 0.13333333 | AS68: =40/60 -> 0.66666667
F69: false neg | G69: 10 | H69: 7 | I69: 4 | J69: 2 | K69: 11 | L69: 9 | M69: 4 | N69: 1 | U69: =40/60 -> 0.66666667
F71: F.N/F.P | G71: =G69/G67 -> 1.25 | H71: =H69/H67 -> 0.77777778 | I71: =I69/I67 -> 1.3333333 | J71: =J69/J67 -> 0.66666667 | K71: =K69/K67 -> 3.6666667 | L71: =L69/L67 -> 1 | M71: =M69/M67 -> 0.44444444 | N71: =N69/N67 -> 0.25
F72: FN or A /FP | G72: =(G69+G65)/G67 -> 1.875 | H72: =(H69+H65)/H67 -> 1.6666667 | I72: =(I69+I65)/I67 -> 5 | J72: =(J69+J65)/J67 -> 5 | K72: =(K69+K65)/K67 -> 5 | L72: =(L69+L65)/L67 -> 1.6666667 | M72: =(M69+M65)/M67 -> 1.6666667 | N72: =(N69+N65)/N67 -> 3.75
F73: F.N. or P / F.P. / count *10 | G73: =(((G69+G65)/G67)/30)*10 -> 0.625 | H73: =(((H69+H65)/H67)/30)*10 -> 0.55555556 | I73: =(((I69+I65)/I67)/30)*10 -> 1.6666667 | J73: =(((J69+J65)/J67)/30)*10 -> 1.6666667 | K73: =(((K69+K65)/K67)/30)*10 -> 1.6666667 | L73: =(((L69+L65)/L67)/30)*10 -> 0.55555556 | M73: =(((M69+M65)/M67)/30)*10 -> 0.55555556 | N73: =(((N69+N65)/N67)/30)*10 -> 1.25
F75: A / F.P | G75: =((G65/G67)) -> 0.625 | H75: =((H65/H67)/H69)*10 -> 1.2698413 | I75: =((I65/I67)/I69)*10 -> 9.1666667 | J75: =((J65/J67)/J69)*10 -> 21.666667 | K75: =((K65/K67)/K69)*10 -> 1.2121212 | L75: =((L65/L67)/L69)*10 -> 0.74074074 | M75: =((M65/M67)/M69)*10 -> 3.0555556 | N75: =((N65/N67)/N69)*10 -> 35
F76: F.N./30 | G76: =G69/30 -> 0.33333333 | H76: =H69/30 -> 0.23333333 | I76: =I69/30 -> 0.13333333 | J76: =J69/30 -> 0.066666667 | K76: =K69/30 -> 0.36666667 | L76: =L69/30 -> 0.3 | M76: =M69/30 -> 0.13333333 | N76: =N69/30 -> 0.033333333
F77: * | G77: =G75*G76 -> 0.20833333 | H77: =H75*H76 -> 0.2962963 | I77: =I75*I76 -> 1.2222222 | J77: =J75*J76 -> 1.4444444 | K77: =K75*K76 -> 0.44444444 | L77: =L75*L76 -> 0.22222222 | M77: =M75*M76 -> 0.40740741 | N77: =N75*N76 -> 1.1666667
F80: Cat % | G80: =G64/60 -> 0.21666667 | H80: =H64/60 -> 0.28333333 | I80: =I64/60 -> 0.23333333 | J80: =J64/60 -> 0.26666667 | K80: =K64/60 -> 0.11666667 | L80: =L64/60 -> 0.25 | M80: =M64/60 -> 0.33333333 | N80: =N64/60 -> 0.3
F81: catcount*prob fals pos | G81: =G80*G68 -> 0.057777778 | H81: =H80*H68 -> 0.085 | I81: =I80*I68 -> 0.023333333 | J81: =J80*J68 -> 0.026666667 | K81: =K80*K68 -> 0.011666667 | L81: =L80*L68 -> 0.075 | M81: =M80*M68 -> 0.1 | N81: =N80*N68 -> 0.04
F82: Root cat% / Root accuracy% | G82: =G80^0.5/G66^0.5 -> 1.6124515 | H82: =H80^0.5/H66^0.5 -> 1.457738 | I82: =I80^0.5/I66^0.5 -> 1.1281521 | J82: =J80^0.5/J66^0.5 -> 1.1094004 | K82: =K80^0.5/K66^0.5 -> 1.3228757 | L82: =L80^0.5/L66^0.5 -> 1.5811388 | M82: =M80^0.5/M66^0.5 -> 1.3483997 | N82: =N80^0.5/N66^0.5 -> 1.1338934
F85: 1-cat% | G85: =1-(G64/60) -> 0.78333333 | H85: =1-(H64/60) -> 0.71666667 | I85: =1-(I64/60) -> 0.76666667 | J85: =1-(J64/60) -> 0.73333333 | K85: =1-(K64/60) -> 0.88333333 | L85: =1-(L64/60) -> 0.75 | M85: =1-(M64/60) -> 0.66666667 | N85: =1-(N64/60) -> 0.7
F86: 1-acc% | G86: =1-G66 -> 0.91666667 | H86: =1-H66 -> 0.86666667 | I86: =1-I66 -> 0.81666667 | J86: =1-J66 -> 0.78333333 | K86: =1-K66 -> 0.93333333 | L86: =1-L66 -> 0.9 | M86: =1-M66 -> 0.81666667 | N86: =1-N66 -> 0.76666667

Sheet Sheet1
A1: Log reg | B1: Accurate | G1: False Pos | K1: False neg | Q1: NB | R1: Accurate | W1: False Pos | AA1: False neg
A2: road | B2: safety | C2: waste | D2: water | F2: road | G2: safety | H2: waste | I2: water | K2: road | L2: safety | M2: waste | N2: water | Q2: road | R2: safety | S2: waste | T2: water | V2: road | W2: safety | X2: waste | Y2: water | AA2: road | AB2: safety | AC2: waste | AD2: water
A3: =AND(IF(predictwithfallbackConfidences!$E3=predictwithfallbackConfidences!$B3,1,0),IF(predictwithfallbackConfidences!$E3=Sheet1!A$2,1,0)) -> TRUE | B3: =AND(IF(predictwithfallbackConfidences!$E3=predictwithfallbackConfidences!$B3,1,0),IF(predictwithfallbackConfidences!$E3=Sheet1!B$2,1,0)) -> FALSE | C3: =AND(IF(predictwithfallbackConfidences!$E3=predictwithfallbackConfidences!$B3,1,0),IF(predictwithfallbackConfidences!$E3=Sheet1!C$2,1,0)) -> FALSE | D3: =AND(IF(predictwithfallbackConfidences!$E3=predictwithfallbackConfidences!$B3,1,0),IF(predictwithfallbackConfidences!$E3=Sheet1!D$2,1,0)) -> FALSE | F3: =AND(IF(predictwithfallbackConfidences!$E3=predictwithfallbackConfidences!$B3,0,1),IF(predictwithfallbackConfidences!$E3=Sheet1!A$2,1,0)) -> FALSE | G3: =AND(IF(predictwithfallbackConfidences!$E3=predictwithfallbackConfidences!$B3,0,1),IF(predictwithfallbackConfidences!$E3=Sheet1!B$2,1,0)) -> FALSE | H3: =AND(IF(predictwithfallbackConfidences!$E3=predictwithfallbackConfidences!$B3,0,1),IF(predictwithfallbackConfidences!$E3=Sheet1!C$2,1,0)) -> FALSE | I3: =AND(IF(predictwithfallbackConfidences!$E3=predictwithfallbackConfidences!$B3,0,1),IF(predictwithfallbackConfidences!$E3=Sheet1!D$2,1,0)) -> FALSE | K3: =AND(IF(predictwithfallbackConfidences!$E3=predictwithfallbackConfidences!$B3,0,1),IF(predictwithfallbackConfidences!$B3=Sheet1!A$2,1,0)) -> FALSE | L3: =AND(IF(predictwithfallbackConfidences!$E3=predictwithfallbackConfidences!$B3,0,1),IF(predictwithfallbackConfidences!$B3=Sheet1!B$2,1,0)) -> FALSE | M3: =AND(IF(predictwithfallbackConfidences!$E3=predictwithfallbackConfidences!$B3,0,1),IF(predictwithfallbackConfidences!$B3=Sheet1!C$2,1,0)) -> FALSE | N3: =AND(IF(predictwithfallbackConfidences!$E3=predictwithfallbackConfidences!$B3,0,1),IF(predictwithfallbackConfidences!$B3=Sheet1!D$2,1,0)) -> FALSE | Q3: =AND(IF(predictwithfallbackConfidences!$F3=predictwithfallbackConfidences!$B3,1,0),IF(predictwithfallbackConfidences!$F3=Sheet1!A$2,1,0)) -> FALSE | R3: =AND(IF(predictwithfallbackConfidences!$F3=predictwithfallbackConfidences!$B3,1,0),IF(predictwithfallbackConfidences!$F3=Sheet1!B$2,1,0)) -> FALSE | S3: =AND(IF(predictwithfallbackConfidences!$F3=predictwithfallbackConfidences!$B3,1,0),IF(predictwithfallbackConfidences!$F3=Sheet1!C$2,1,0)) -> FALSE | T3: =AND(IF(predictwithfallbackConfidences!$F3=predictwithfallbackConfidences!$B3,1,0),IF(predictwithfallbackConfidences!$F3=Sheet1!D$2,1,0)) -> FALSE | V3: =AND(IF(predictwithfallbackConfidences!$F3=predictwithfallbackConfidences!$B3,0,1),IF(predictwithfallbackConfidences!$F3=Sheet1!A$2,1,0)) -> FALSE | W3: =AND(IF(predictwithfallbackConfidences!$F3=predictwithfallbackConfidences!$B3,0,1),IF(predictwithfallbackConfidences!$F3=Sheet1!B$2,1,0)) -> TRUE | X3: =AND(IF(predictwithfallbackConfidences!$F3=predictwithfallbackConfidences!$B3,0,1),IF(predictwithfallbackConfidences!$F3=Sheet1!C$2,1,0)) -> FALSE | Y3: =AND(IF(predictwithfallbackConfidences!$F3=predictwithfallbackConfidences!$B3,0,1),IF(predictwithfallbackConfidences!$F3=Sheet1!D$2,1,0)) -> FALSE | AA3: =AND(IF(predictwithfallbackConfidences!$F3=predictwithfallbackConfidences!$B3,0,1),IF(predictwithfallbackConfidences!$B3=Sheet1!A$2,1,0)) -> TRUE | AB3: =AND(IF(predictwithfallbackConfidences!$F3=predictwithfallbackConfidences!$B3,0,1),IF(predictwithfallbackConfidences!$B3=Sheet1!B$2,1,0)) -> FALSE | AC3: =AND(IF(predictwithfallbackConfidences!$F3=predictwithfallbackConfidences!$B3,0,1),IF(predictwithfallbackConfidences!$B3=Sheet1!C$2,1,0)) -> FALSE | AD3: =AND(IF(predictwithfallbackConfidences!$F3=predictwithfallbackConfidences!$B3,0,1),IF(predictwithfallbackConfidences!$B3=Sheet1!D$2,1,0)) -> FALSE
A4: =AND(IF(predictwithfallbackConfidences!$E4=predictwithfallbackConfidences!$B4,1,0),IF(predictwithfallbackConfidences!$E4=Sheet1!A$2,1,0)) -> FALSE | B4: =AND(IF(predictwithfallbackConfidences!$E4=predictwithfallbackConfidences!$B4,1,0),IF(predictwithfallbackConfidences!$E4=Sheet1!B$2,1,0)) -> FALSE | C4: =AND(IF(predictwithfallbackConfidences!$E4=predictwithfallbackConfidences!$B4,1,0),IF(predictwithfallbackConfidences!$E4=Sheet1!C$2,1,0)) -> FALSE | D4: =AND(IF(predictwithfallbackConfidences!$E4=predictwithfallbackConfidences!$B4,1,0),IF(predictwithfallbackConfidences!$E4=Sheet1!D$2,1,0)) -> FALSE | F4: =AND(IF(predictwithfallbackConfidences!$E4=predictwithfallbackConfidences!$B4,0,1),IF(predictwithfallbackConfidences!$E4=Sheet1!A$2,1,0)) -> FALSE | G4: =AND(IF(predictwithfallbackConfidences!$E4=predictwithfallbackConfidences!$B4,0,1),IF(predictwithfallbackConfidences!$E4=Sheet1!B$2,1,0)) -> TRUE | H4: =AND(IF(predictwithfallbackConfidences!$E4=predictwithfallbackConfidences!$B4,0,1),IF(predictwithfallbackConfidences!$E4=Sheet1!C$2,1,0)) -> FALSE | I4: =AND(IF(predictwithfallbackConfidences!$E4=predictwithfallbackConfidences!$B4,0,1),IF(predictwithfallbackConfidences!$E4=Sheet1!D$2,1,0)) -> FALSE | K4: =AND(IF(predictwithfallbackConfidences!$E4=predictwithfallbackConfidences!$B4,0,1),IF(predictwithfallbackConfidences!$B4=Sheet1!A$2,1,0)) -> TRUE | L4: =AND(IF(predictwithfallbackConfidences!$E4=predictwithfallbackConfidences!$B4,0,1),IF(predictwithfallbackConfidences!$B4=Sheet1!B$2,1,0)) -> FALSE | M4: =AND(IF(predictwithfallbackConfidences!$E4=predictwithfallbackConfidences!$B4,0,1),IF(predictwithfallbackConfidences!$B4=Sheet1!C$2,1,0)) -> FALSE | N4: =AND(IF(predictwithfallbackConfidences!$E4=predictwithfallbackConfidences!$B4,0,1),IF(predictwithfallbackConfidences!$B4=Sheet1!D$2,1,0)) -> FALSE | Q4: =AND(IF(predictwithfallbackConfidences!$F4=predictwithfallbackConfidences!$B4,1,0),IF(predictwithfallbackConfidences!$F4=Sheet1!A$2,1,0)) -> FALSE | R4: =AND(IF(predictwithfallbackConfidences!$F4=predictwithfallbackConfidences!$B4,1,0),IF(predictwithfallbackConfidences!$F4=Sheet1!B$2,1,0)) -> FALSE | S4: =AND(IF(predictwithfallbackConfidences!$F4=predictwithfallbackConfidences!$B4,1,0),IF(predictwithfallbackConfidences!$F4=Sheet1!C$2,1,0)) -> FALSE | T4: =AND(IF(predictwithfallbackConfidences!$F4=predictwithfallbackConfidences!$B4,1,0),IF(predictwithfallbackConfidences!$F4=Sheet1!D$2,1,0)) -> FALSE | V4: =AND(IF(predictwithfallbackConfidences!$F4=predictwithfallbackConfidences!$B4,0,1),IF(predictwithfallbackConfidences!$F4=Sheet1!A$2,1,0)) -> FALSE | W4: =AND(IF(predictwithfallbackConfidences!$F4=predictwithfallbackConfidences!$B4,0,1),IF(predictwithfallbackConfidences!$F4=Sheet1!B$2,1,0)) -> FALSE | X4: =AND(IF(predictwithfallbackConfidences!$F4=predictwithfallbackConfidences!$B4,0,1),IF(predictwithfallbackConfidences!$F4=Sheet1!C$2,1,0)) -> TRUE | Y4: =AND(IF(predictwithfallbackConfidences!$F4=predictwithfallbackConfidences!$B4,0,1),IF(predictwithfallbackConfidences!$F4=Sheet1!D$2,1,0)) -> FALSE | AA4: =AND(IF(predictwithfallbackConfidences!$F4=predictwithfallbackConfidences!$B4,0,1),IF(predictwithfallbackConfidences!$B4=Sheet1!A$2,1,0)) -> TRUE | AB4: =AND(IF(predictwithfallbackConfidences!$F4=predictwithfallbackConfidences!$B4,0,1),IF(predictwithfallbackConfidences!$B4=Sheet1!B$2,1,0)) -> FALSE | AC4: =AND(IF(predictwithfallbackConfidences!$F4=predictwithfallbackConfidences!$B4,0,1),IF(predictwithfallbackConfidences!$B4=Sheet1!C$2,1,0)) -> FALSE | AD4: =AND(IF(predictwithfallbackConfidences!$F4=predictwithfallbackConfidences!$B4,0,1),IF(predictwithfallbackConfidences!$B4=Sheet1!D$2,1,0)) -> FALSE | AG4: Log reg accuracy matrix
A5: =AND(IF(predictwithfallbackConfidences!$E5=predictwithfallbackConfidences!$B5,1,0),IF(predictwithfallbackConfidences!$E5=Sheet1!A$2,1,0)) -> TRUE | B5: =AND(IF(predictwithfallbackConfidences!$E5=predictwithfallbackConfidences!$B5,1,0),IF(predictwithfallbackConfidences!$E5=Sheet1!B$2,1,0)) -> FALSE | C5: =AND(IF(predictwithfallbackConfidences!$E5=predictwithfallbackConfidences!$B5,1,0),IF(predictwithfallbackConfidences!$E5=Sheet1!C$2,1,0)) -> FALSE | D5: =AND(IF(predictwithfallbackConfidences!$E5=predictwithfallbackConfidences!$B5,1,0),IF(predictwithfallbackConfidences!$E5=Sheet1!D$2,1,0)) -> FALSE | F5: =AND(IF(predictwithfallbackConfidences!$E5=predictwithfallbackConfidences!$B5,0,1),IF(predictwithfallbackConfidences!$E5=Sheet1!A$2,1,0)) -> FALSE | G5: =AND(IF(predictwithfallbackConfidences!$E5=predictwithfallbackConfidences!$B5,0,1),IF(predictwithfallbackConfidences!$E5=Sheet1!B$2,1,0)) -> FALSE | H5: =AND(IF(predictwithfallbackConfidences!$E5=predictwithfallbackConfidences!$B5,0,1),IF(predictwithfallbackConfidences!$E5=Sheet1!C$2,1,0)) -> FALSE | I5: =AND(IF(predictwithfallbackConfidences!$E5=predictwithfallbackConfidences!$B5,0,1),IF(predictwithfallbackConfidences!$E5=Sheet1!D$2,1,0)) -> FALSE | K5: =AND(IF(predictwithfallbackConfidences!$E5=predictwithfallbackConfidences!$B5,0,1),IF(predictwithfallbackConfidences!$B5=Sheet1!A$2,1,0)) -> FALSE | L5: =AND(IF(predictwithfallbackConfidences!$E5=predictwithfallbackConfidences!$B5,0,1),IF(predictwithfallbackConfidences!$B5=Sheet1!B$2,1,0)) -> FALSE | M5: =AND(IF(predictwithfallbackConfidences!$E5=predictwithfallbackConfidences!$B5,0,1),IF(predictwithfallbackConfidences!$B5=Sheet1!C$2,1,0)) -> FALSE | N5: =AND(IF(predictwithfallbackConfidences!$E5=predictwithfallbackConfidences!$B5,0,1),IF(predictwithfallbackConfidences!$B5=Sheet1!D$2,1,0)) -> FALSE | Q5: =AND(IF(predictwithfallbackConfidences!$F5=predictwithfallbackConfidences!$B5,1,0),IF(predictwithfallbackConfidences!$F5=Sheet1!A$2,1,0)) -> TRUE | R5: =AND(IF(predictwithfallbackConfidences!$F5=predictwithfallbackConfidences!$B5,1,0),IF(predictwithfallbackConfidences!$F5=Sheet1!B$2,1,0)) -> FALSE | S5: =AND(IF(predictwithfallbackConfidences!$F5=predictwithfallbackConfidences!$B5,1,0),IF(predictwithfallbackConfidences!$F5=Sheet1!C$2,1,0)) -> FALSE | T5: =AND(IF(predictwithfallbackConfidences!$F5=predictwithfallbackConfidences!$B5,1,0),IF(predictwithfallbackConfidences!$F5=Sheet1!D$2,1,0)) -> FALSE | V5: =AND(IF(predictwithfallbackConfidences!$F5=predictwithfallbackConfidences!$B5,0,1),IF(predictwithfallbackConfidences!$F5=Sheet1!A$2,1,0)) -> FALSE | W5: =AND(IF(predictwithfallbackConfidences!$F5=predictwithfallbackConfidences!$B5,0,1),IF(predictwithfallbackConfidences!$F5=Sheet1!B$2,1,0)) -> FALSE | X5: =AND(IF(predictwithfallbackConfidences!$F5=predictwithfallbackConfidences!$B5,0,1),IF(predictwithfallbackConfidences!$F5=Sheet1!C$2,1,0)) -> FALSE | Y5: =AND(IF(predictwithfallbackConfidences!$F5=predictwithfallbackConfidences!$B5,0,1),IF(predictwithfallbackConfidences!$F5=Sheet1!D$2,1,0)) -> FALSE | AA5: =AND(IF(predictwithfallbackConfidences!$F5=predictwithfallbackConfidences!$B5,0,1),IF(predictwithfallbackConfidences!$B5=Sheet1!A$2,1,0)) -> FALSE | AB5: =AND(IF(predictwithfallbackConfidences!$F5=predictwithfallbackConfidences!$B5,0,1),IF(predictwithfallbackConfidences!$B5=Sheet1!B$2,1,0)) -> FALSE | AC5: =AND(IF(predictwithfallbackConfidences!$F5=predictwithfallbackConfidences!$B5,0,1),IF(predictwithfallbackConfidences!$B5=Sheet1!C$2,1,0)) -> FALSE | AD5: =AND(IF(predictwithfallbackConfidences!$F5=predictwithfallbackConfidences!$B5,0,1),IF(predictwithfallbackConfidences!$B5=Sheet1!D$2,1,0)) -> FALSE | AG5: road | AH5: safety | AI5: waste | AJ5: water
A6: =AND(IF(predictwithfallbackConfidences!$E6=predictwithfallbackConfidences!$B6,1,0),IF(predictwithfallbackConfidences!$E6=Sheet1!A$2,1,0)) -> TRUE | B6: =AND(IF(predictwithfallbackConfidences!$E6=predictwithfallbackConfidences!$B6,1,0),IF(predictwithfallbackConfidences!$E6=Sheet1!B$2,1,0)) -> FALSE | C6: =AND(IF(predictwithfallbackConfidences!$E6=predictwithfallbackConfidences!$B6,1,0),IF(predictwithfallbackConfidences!$E6=Sheet1!C$2,1,0)) -> FALSE | D6: =AND(IF(predictwithfallbackConfidences!$E6=predictwithfallbackConfidences!$B6,1,0),IF(predictwithfallbackConfidences!$E6=Sheet1!D$2,1,0)) -> FALSE | F6: =AND(IF(predictwithfallbackConfidences!$E6=predictwithfallbackConfidences!$B6,0,1),IF(predictwithfallbackConfidences!$E6=Sheet1!A$2,1,0)) -> FALSE | G6: =AND(IF(predictwithfallbackConfidences!$E6=predictwithfallbackConfidences!$B6,0,1),IF(predictwithfallbackConfidences!$E6=Sheet1!B$2,1,0)) -> FALSE | H6: =AND(IF(predictwithfallbackConfidences!$E6=predictwithfallbackConfidences!$B6,0,1),IF(predictwithfallbackConfidences!$E6=Sheet1!C$2,1,0)) -> FALSE | I6: =AND(IF(predictwithfallbackConfidences!$E6=predictwithfallbackConfidences!$B6,0,1),IF(predictwithfallbackConfidences!$E6=Sheet1!D$2,1,0)) -> FALSE | K6: =AND(IF(predictwithfallbackConfidences!$E6=predictwithfallbackConfidences!$B6,0,1),IF(predictwithfallbackConfidences!$B6=Sheet1!A$2,1,0)) -> FALSE | L6: =AND(IF(predictwithfallbackConfidences!$E6=predictwithfallbackConfidences!$B6,0,1),IF(predictwithfallbackConfidences!$B6=Sheet1!B$2,1,0)) -> FALSE | M6: =AND(IF(predictwithfallbackConfidences!$E6=predictwithfallbackConfidences!$B6,0,1),IF(predictwithfallbackConfidences!$B6=Sheet1!C$2,1,0)) -> FALSE | N6: =AND(IF(predictwithfallbackConfidences!$E6=predictwithfallbackConfidences!$B6,0,1),IF(predictwithfallbackConfidences!$B6=Sheet1!D$2,1,0)) -> FALSE | Q6: =AND(IF(predictwithfallbackConfidences!$F6=predictwithfallbackConfidences!$B6,1,0),IF(predictwithfallbackConfidences!$F6=Sheet1!A$2,1,0)) -> TRUE | R6: =AND(IF(predictwithfallbackConfidences!$F6=predictwithfallbackConfidences!$B6,1,0),IF(predictwithfallbackConfidences!$F6=Sheet1!B$2,1,0)) -> FALSE | S6: =AND(IF(predictwithfallbackConfidences!$F6=predictwithfallbackConfidences!$B6,1,0),IF(predictwithfallbackConfidences!$F6=Sheet1!C$2,1,0)) -> FALSE | T6: =AND(IF(predictwithfallbackConfidences!$F6=predictwithfallbackConfidences!$B6,1,0),IF(predictwithfallbackConfidences!$F6=Sheet1!D$2,1,0)) -> FALSE | V6: =AND(IF(predictwithfallbackConfidences!$F6=predictwithfallbackConfidences!$B6,0,1),IF(predictwithfallbackConfidences!$F6=Sheet1!A$2,1,0)) -> FALSE | W6: =AND(IF(predictwithfallbackConfidences!$F6=predictwithfallbackConfidences!$B6,0,1),IF(predictwithfallbackConfidences!$F6=Sheet1!B$2,1,0)) -> FALSE | X6: =AND(IF(predictwithfallbackConfidences!$F6=predictwithfallbackConfidences!$B6,0,1),IF(predictwithfallbackConfidences!$F6=Sheet1!C$2,1,0)) -> FALSE | Y6: =AND(IF(predictwithfallbackConfidences!$F6=predictwithfallbackConfidences!$B6,0,1),IF(predictwithfallbackConfidences!$F6=Sheet1!D$2,1,0)) -> FALSE | AA6: =AND(IF(predictwithfallbackConfidences!$F6=predictwithfallbackConfidences!$B6,0,1),IF(predictwithfallbackConfidences!$B6=Sheet1!A$2,1,0)) -> FALSE | AB6: =AND(IF(predictwithfallbackConfidences!$F6=predictwithfallbackConfidences!$B6,0,1),IF(predictwithfallbackConfidences!$B6=Sheet1!B$2,1,0)) -> FALSE | AC6: =AND(IF(predictwithfallbackConfidences!$F6=predictwithfallbackConfidences!$B6,0,1),IF(predictwithfallbackConfidences!$B6=Sheet1!C$2,1,0)) -> FALSE | AD6: =AND(IF(predictwithfallbackConfidences!$F6=predictwithfallbackConfidences!$B6,0,1),IF(predictwithfallbackConfidences!$B6=Sheet1!D$2,1,0)) -> FALSE | AF6: accurate | AG6: 5 | AH6: 8 | AI6: 11 | AJ6: 13
